[2025-09-28T23:14:52.709+0000] {taskinstance.py:1087} INFO - Dependencies all met for <TaskInstance: dag2.transform_and_save_to_hadoop scheduled__2023-05-18T00:00:00+00:00 [queued]>
[2025-09-28T23:14:52.720+0000] {taskinstance.py:1087} INFO - Dependencies all met for <TaskInstance: dag2.transform_and_save_to_hadoop scheduled__2023-05-18T00:00:00+00:00 [queued]>
[2025-09-28T23:14:52.720+0000] {taskinstance.py:1283} INFO - 
--------------------------------------------------------------------------------
[2025-09-28T23:14:52.720+0000] {taskinstance.py:1284} INFO - Starting attempt 1 of 1
[2025-09-28T23:14:52.720+0000] {taskinstance.py:1285} INFO - 
--------------------------------------------------------------------------------
[2025-09-28T23:14:52.757+0000] {taskinstance.py:1304} INFO - Executing <Task(PythonOperator): transform_and_save_to_hadoop> on 2023-05-18 00:00:00+00:00
[2025-09-28T23:14:52.765+0000] {standard_task_runner.py:55} INFO - Started process 1643 to run task
[2025-09-28T23:14:52.768+0000] {standard_task_runner.py:82} INFO - Running: ['airflow', 'tasks', 'run', 'dag2', 'transform_and_save_to_hadoop', 'scheduled__2023-05-18T00:00:00+00:00', '--job-id', '291', '--raw', '--subdir', 'DAGS_FOLDER/dag2.py', '--cfg-path', '/tmp/tmp7mlvy8cg']
[2025-09-28T23:14:52.770+0000] {standard_task_runner.py:83} INFO - Job 291: Subtask transform_and_save_to_hadoop
[2025-09-28T23:14:52.842+0000] {task_command.py:389} INFO - Running <TaskInstance: dag2.transform_and_save_to_hadoop scheduled__2023-05-18T00:00:00+00:00 [running]> on host 37e0d29c4e5f
[2025-09-28T23:14:52.933+0000] {taskinstance.py:1513} INFO - Exporting the following env vars:
AIRFLOW_CTX_DAG_OWNER=airflow
AIRFLOW_CTX_DAG_ID=dag2
AIRFLOW_CTX_TASK_ID=transform_and_save_to_hadoop
AIRFLOW_CTX_EXECUTION_DATE=2023-05-18T00:00:00+00:00
AIRFLOW_CTX_TRY_NUMBER=1
AIRFLOW_CTX_DAG_RUN_ID=scheduled__2023-05-18T00:00:00+00:00
[2025-09-28T23:14:52.936+0000] {client.py:192} INFO - Instantiated <InsecureClient(url='http://hadoop:9870')>.
[2025-09-28T23:14:52.938+0000] {taskinstance.py:1772} ERROR - Task failed with exception
Traceback (most recent call last):
  File "/home/airflow/.local/lib/python3.7/site-packages/airflow/operators/python.py", line 175, in execute
    return_value = self.execute_callable()
  File "/home/airflow/.local/lib/python3.7/site-packages/airflow/operators/python.py", line 192, in execute_callable
    return self.python_callable(*self.op_args, **self.op_kwargs)
  File "/opt/airflow/dags/dag2.py", line 20, in transform_and_save_to_hadoop
    cursor.execute("SELECT * FROM tabela2")
  File "/home/airflow/.local/lib/python3.7/site-packages/pymysql/cursors.py", line 153, in execute
    result = self._query(query)
  File "/home/airflow/.local/lib/python3.7/site-packages/pymysql/cursors.py", line 322, in _query
    conn.query(q)
  File "/home/airflow/.local/lib/python3.7/site-packages/pymysql/connections.py", line 563, in query
    self._affected_rows = self._read_query_result(unbuffered=unbuffered)
  File "/home/airflow/.local/lib/python3.7/site-packages/pymysql/connections.py", line 825, in _read_query_result
    result.read()
  File "/home/airflow/.local/lib/python3.7/site-packages/pymysql/connections.py", line 1199, in read
    first_packet = self.connection._read_packet()
  File "/home/airflow/.local/lib/python3.7/site-packages/pymysql/connections.py", line 775, in _read_packet
    packet.raise_for_error()
  File "/home/airflow/.local/lib/python3.7/site-packages/pymysql/protocol.py", line 219, in raise_for_error
    err.raise_mysql_exception(self._data)
  File "/home/airflow/.local/lib/python3.7/site-packages/pymysql/err.py", line 150, in raise_mysql_exception
    raise errorclass(errno, errval)
pymysql.err.ProgrammingError: (1146, "Table 'db***.tabela2' doesn't exist")
[2025-09-28T23:14:52.947+0000] {taskinstance.py:1327} INFO - Marking task as FAILED. dag_id=dag2, task_id=transform_and_save_to_hadoop, execution_date=20230518T000000, start_date=20250928T231452, end_date=20250928T231452
[2025-09-28T23:14:52.973+0000] {standard_task_runner.py:105} ERROR - Failed to execute job 291 for task transform_and_save_to_hadoop ((1146, "Table 'db***.tabela2' doesn't exist"); 1643)
[2025-09-28T23:14:53.020+0000] {local_task_job.py:159} INFO - Task exited with return code 1
[2025-09-28T23:14:53.129+0000] {taskinstance.py:2582} INFO - 0 downstream tasks scheduled from follow-on schedule check
