[2025-09-28T23:14:20.131+0000] {taskinstance.py:1087} INFO - Dependencies all met for <TaskInstance: dag3.transform_and_save_to_hadoop scheduled__2023-04-07T00:00:00+00:00 [queued]>
[2025-09-28T23:14:20.142+0000] {taskinstance.py:1087} INFO - Dependencies all met for <TaskInstance: dag3.transform_and_save_to_hadoop scheduled__2023-04-07T00:00:00+00:00 [queued]>
[2025-09-28T23:14:20.142+0000] {taskinstance.py:1283} INFO - 
--------------------------------------------------------------------------------
[2025-09-28T23:14:20.142+0000] {taskinstance.py:1284} INFO - Starting attempt 1 of 1
[2025-09-28T23:14:20.143+0000] {taskinstance.py:1285} INFO - 
--------------------------------------------------------------------------------
[2025-09-28T23:14:20.168+0000] {taskinstance.py:1304} INFO - Executing <Task(PythonOperator): transform_and_save_to_hadoop> on 2023-04-07 00:00:00+00:00
[2025-09-28T23:14:20.176+0000] {standard_task_runner.py:55} INFO - Started process 1446 to run task
[2025-09-28T23:14:20.179+0000] {standard_task_runner.py:82} INFO - Running: ['airflow', 'tasks', 'run', 'dag3', 'transform_and_save_to_hadoop', 'scheduled__2023-04-07T00:00:00+00:00', '--job-id', '203', '--raw', '--subdir', 'DAGS_FOLDER/dag3.py', '--cfg-path', '/tmp/tmpbz0_q7sr']
[2025-09-28T23:14:20.181+0000] {standard_task_runner.py:83} INFO - Job 203: Subtask transform_and_save_to_hadoop
[2025-09-28T23:14:20.256+0000] {task_command.py:389} INFO - Running <TaskInstance: dag3.transform_and_save_to_hadoop scheduled__2023-04-07T00:00:00+00:00 [running]> on host 37e0d29c4e5f
[2025-09-28T23:14:20.351+0000] {taskinstance.py:1513} INFO - Exporting the following env vars:
AIRFLOW_CTX_DAG_OWNER=airflow
AIRFLOW_CTX_DAG_ID=dag3
AIRFLOW_CTX_TASK_ID=transform_and_save_to_hadoop
AIRFLOW_CTX_EXECUTION_DATE=2023-04-07T00:00:00+00:00
AIRFLOW_CTX_TRY_NUMBER=1
AIRFLOW_CTX_DAG_RUN_ID=scheduled__2023-04-07T00:00:00+00:00
[2025-09-28T23:14:20.353+0000] {client.py:192} INFO - Instantiated <InsecureClient(url='http://hadoop:9870')>.
[2025-09-28T23:14:20.354+0000] {taskinstance.py:1772} ERROR - Task failed with exception
Traceback (most recent call last):
  File "/home/airflow/.local/lib/python3.7/site-packages/airflow/operators/python.py", line 175, in execute
    return_value = self.execute_callable()
  File "/home/airflow/.local/lib/python3.7/site-packages/airflow/operators/python.py", line 192, in execute_callable
    return self.python_callable(*self.op_args, **self.op_kwargs)
  File "/opt/airflow/dags/dag3.py", line 20, in transform_and_save_to_hadoop
    cursor.execute("SELECT * FROM tabela3")
  File "/home/airflow/.local/lib/python3.7/site-packages/pymysql/cursors.py", line 153, in execute
    result = self._query(query)
  File "/home/airflow/.local/lib/python3.7/site-packages/pymysql/cursors.py", line 322, in _query
    conn.query(q)
  File "/home/airflow/.local/lib/python3.7/site-packages/pymysql/connections.py", line 563, in query
    self._affected_rows = self._read_query_result(unbuffered=unbuffered)
  File "/home/airflow/.local/lib/python3.7/site-packages/pymysql/connections.py", line 825, in _read_query_result
    result.read()
  File "/home/airflow/.local/lib/python3.7/site-packages/pymysql/connections.py", line 1199, in read
    first_packet = self.connection._read_packet()
  File "/home/airflow/.local/lib/python3.7/site-packages/pymysql/connections.py", line 775, in _read_packet
    packet.raise_for_error()
  File "/home/airflow/.local/lib/python3.7/site-packages/pymysql/protocol.py", line 219, in raise_for_error
    err.raise_mysql_exception(self._data)
  File "/home/airflow/.local/lib/python3.7/site-packages/pymysql/err.py", line 150, in raise_mysql_exception
    raise errorclass(errno, errval)
pymysql.err.ProgrammingError: (1146, "Table 'db***.tabela3' doesn't exist")
[2025-09-28T23:14:20.360+0000] {taskinstance.py:1327} INFO - Marking task as FAILED. dag_id=dag3, task_id=transform_and_save_to_hadoop, execution_date=20230407T000000, start_date=20250928T231420, end_date=20250928T231420
[2025-09-28T23:14:20.382+0000] {standard_task_runner.py:105} ERROR - Failed to execute job 203 for task transform_and_save_to_hadoop ((1146, "Table 'db***.tabela3' doesn't exist"); 1446)
[2025-09-28T23:14:20.391+0000] {local_task_job.py:159} INFO - Task exited with return code 1
[2025-09-28T23:14:20.403+0000] {taskinstance.py:2582} INFO - 0 downstream tasks scheduled from follow-on schedule check
